2024-01-13 07:27:08 default[20240112t232125]  "GET / HTTP/1.1" 500
2024-01-13 07:27:09 default[20240112t232125]  [2024-01-13 07:27:09 +0000] [11] [INFO] Starting gunicorn 21.2.0
2024-01-13 07:27:09 default[20240112t232125]  [2024-01-13 07:27:09 +0000] [11] [INFO] Listening at: http://0.0.0.0:8081 (11)
2024-01-13 07:27:09 default[20240112t232125]  [2024-01-13 07:27:09 +0000] [11] [INFO] Using worker: gthread
2024-01-13 07:27:09 default[20240112t232125]  [2024-01-13 07:27:09 +0000] [19] [INFO] Booting worker with pid: 19
2024-01-13 07:27:09 default[20240112t232125]  [2024-01-13 07:27:09 +0000] [19] [ERROR] Exception in worker process
2024-01-13 07:27:09 default[20240112t232125]  Traceback (most recent call last):    File "/layers/google.python.pip/pip/lib/python3.9/site-packages/gunicorn/arbiter.py", line 609, in spawn_worker      worker.init_process()    File "/layers/google.python.pip/pip/lib/python3.9/site-packages/gunicorn/workers/gthread.py", line 95, in init_process      super().init_process()    File "/layers/google.python.pip/pip/lib/python3.9/site-packages/gunicorn/workers/base.py", line 134, in init_process      self.load_wsgi()    File "/layers/google.python.pip/pip/lib/python3.9/site-packages/gunicorn/workers/base.py", line 146, in load_wsgi      self.wsgi = self.app.wsgi()    File "/layers/google.python.pip/pip/lib/python3.9/site-packages/gunicorn/app/base.py", line 67, in wsgi      self.callable = self.load()    File "/layers/google.python.pip/pip/lib/python3.9/site-packages/gunicorn/app/wsgiapp.py", line 58, in load      return self.load_wsgiapp()    File "/layers/google.python.pip/pip/lib/python3.9/site-packages/gunicorn/app/wsgiapp.py", line 48, in load_wsgiapp      return util.import_app(self.app_uri)    File "/layers/google.python.pip/pip/lib/python3.9/site-packages/gunicorn/util.py", line 371, in import_app      mod = importlib.import_module(module)    File "/layers/google.python.runtime/python/lib/python3.9/importlib/__init__.py", line 127, in import_module      return _bootstrap._gcd_import(name[level:], package, level)    File "<frozen importlib._bootstrap>", line 1030, in _gcd_import    File "<frozen importlib._bootstrap>", line 1007, in _find_and_load    File "<frozen importlib._bootstrap>", line 984, in _find_and_load_unlocked  ModuleNotFoundError: No module named 'main'
2024-01-13 07:27:09 default[20240112t232125]  [2024-01-13 07:27:09 +0000] [19] [INFO] Worker exiting (pid: 19)
2024-01-13 07:27:09 default[20240112t232125]  [2024-01-13 07:27:09 +0000] [11] [ERROR] Worker (pid:19) exited with code 3
2024-01-13 07:27:09 default[20240112t232125]  [2024-01-13 07:27:09 +0000] [11] [ERROR] Shutting down: Master
2024-01-13 07:27:09 default[20240112t232125]  [2024-01-13 07:27:09 +0000] [11] [ERROR] Reason: Worker failed to boot.
2024-01-13 07:27:09 default[20240112t232125]  [2024-01-13 07:27:09 +0000] [22] [INFO] Booting worker with pid: 22
2024-01-13 07:27:09 default[20240112t232125]  [2024-01-13 07:27:09 +0000] [22] [ERROR] Exception in worker process
2024-01-13 07:27:09 default[20240112t232125]  Traceback (most recent call last):    File "/layers/google.python.pip/pip/lib/python3.9/site-packages/gunicorn/arbiter.py", line 609, in spawn_worker      worker.init_process()    File "/layers/google.python.pip/pip/lib/python3.9/site-packages/gunicorn/workers/gthread.py", line 95, in init_process      super().init_process()    File "/layers/google.python.pip/pip/lib/python3.9/site-packages/gunicorn/workers/base.py", line 134, in init_process      self.load_wsgi()    File "/layers/google.python.pip/pip/lib/python3.9/site-packages/gunicorn/workers/base.py", line 146, in load_wsgi      self.wsgi = self.app.wsgi()    File "/layers/google.python.pip/pip/lib/python3.9/site-packages/gunicorn/app/base.py", line 67, in wsgi      self.callable = self.load()    File "/layers/google.python.pip/pip/lib/python3.9/site-packages/gunicorn/app/wsgiapp.py", line 58, in load      return self.load_wsgiapp()    File "/layers/google.python.pip/pip/lib/python3.9/site-packages/gunicorn/app/wsgiapp.py", line 48, in load_wsgiapp      return util.import_app(self.app_uri)    File "/layers/google.python.pip/pip/lib/python3.9/site-packages/gunicorn/util.py", line 371, in import_app      mod = importlib.import_module(module)    File "/layers/google.python.runtime/python/lib/python3.9/importlib/__init__.py", line 127, in import_module      return _bootstrap._gcd_import(name[level:], package, level)    File "<frozen importlib._bootstrap>", line 1030, in _gcd_import    File "<frozen importlib._bootstrap>", line 1007, in _find_and_load    File "<frozen importlib._bootstrap>", line 984, in _find_and_load_unlocked  ModuleNotFoundError: No module named 'main'
2024-01-13 07:27:09 default[20240112t232125]  [2024-01-13 07:27:09 +0000] [22] [INFO] Worker exiting (pid: 22)
2024-01-13 07:27:14 default[20240112t232125]  "GET / HTTP/1.1" 502
2024-01-13 07:27:14 default[20240112t232125]  [2024-01-13 07:27:14 +0000] [11] [INFO] Starting gunicorn 21.2.0
2024-01-13 07:27:14 default[20240112t232125]  [2024-01-13 07:27:14 +0000] [11] [INFO] Listening at: http://0.0.0.0:8081 (11)
2024-01-13 07:27:14 default[20240112t232125]  [2024-01-13 07:27:14 +0000] [11] [INFO] Using worker: gthread
2024-01-13 07:27:14 default[20240112t232125]  [2024-01-13 07:27:14 +0000] [18] [INFO] Booting worker with pid: 18
2024-01-13 07:27:14 default[20240112t232125]  [2024-01-13 07:27:14 +0000] [18] [ERROR] Exception in worker process
2024-01-13 07:27:14 default[20240112t232125]  Traceback (most recent call last):    File "/layers/google.python.pip/pip/lib/python3.9/site-packages/gunicorn/arbiter.py", line 609, in spawn_worker      worker.init_process()    File "/layers/google.python.pip/pip/lib/python3.9/site-packages/gunicorn/workers/gthread.py", line 95, in init_process      super().init_process()    File "/layers/google.python.pip/pip/lib/python3.9/site-packages/gunicorn/workers/base.py", line 134, in init_process      self.load_wsgi()    File "/layers/google.python.pip/pip/lib/python3.9/site-packages/gunicorn/workers/base.py", line 146, in load_wsgi      self.wsgi = self.app.wsgi()    File "/layers/google.python.pip/pip/lib/python3.9/site-packages/gunicorn/app/base.py", line 67, in wsgi      self.callable = self.load()    File "/layers/google.python.pip/pip/lib/python3.9/site-packages/gunicorn/app/wsgiapp.py", line 58, in load      return self.load_wsgiapp()    File "/layers/google.python.pip/pip/lib/python3.9/site-packages/gunicorn/app/wsgiapp.py", line 48, in load_wsgiapp      return util.import_app(self.app_uri)    File "/layers/google.python.pip/pip/lib/python3.9/site-packages/gunicorn/util.py", line 371, in import_app      mod = importlib.import_module(module)    File "/layers/google.python.runtime/python/lib/python3.9/importlib/__init__.py", line 127, in import_module      return _bootstrap._gcd_import(name[level:], package, level)    File "<frozen importlib._bootstrap>", line 1030, in _gcd_import    File "<frozen importlib._bootstrap>", line 1007, in _find_and_load    File "<frozen importlib._bootstrap>", line 984, in _find_and_load_unlocked  ModuleNotFoundError: No module named 'main'
2024-01-13 07:27:14 default[20240112t232125]  [2024-01-13 07:27:14 +0000] [18] [INFO] Worker exiting (pid: 18)
2024-01-13 07:27:14 default[20240112t232125]  [2024-01-13 07:27:14 +0000] [11] [ERROR] Worker (pid:18) exited with code 3
2024-01-13 07:27:14 default[20240112t232125]  [2024-01-13 07:27:14 +0000] [11] [ERROR] Shutting down: Master
2024-01-13 07:27:14 default[20240112t232125]  [2024-01-13 07:27:14 +0000] [11] [ERROR] Reason: Worker failed to boot.
2024-01-13 07:27:15 default[20240112t232125]  "GET /favicon.ico HTTP/1.1" 500
2024-01-13 07:27:19 default[20240112t232125]  "GET / HTTP/1.1" 502
2024-01-13 07:27:20 default[20240112t232125]  [2024-01-13 07:27:20 +0000] [11] [INFO] Starting gunicorn 21.2.0
2024-01-13 07:27:20 default[20240112t232125]  [2024-01-13 07:27:20 +0000] [11] [INFO] Listening at: http://0.0.0.0:8081 (11)
2024-01-13 07:27:20 default[20240112t232125]  [2024-01-13 07:27:20 +0000] [11] [INFO] Using worker: gthread
2024-01-13 07:27:20 default[20240112t232125]  [2024-01-13 07:27:20 +0000] [20] [INFO] Booting worker with pid: 20
2024-01-13 07:27:20 default[20240112t232125]  [2024-01-13 07:27:20 +0000] [20] [ERROR] Exception in worker process
2024-01-13 07:27:20 default[20240112t232125]  Traceback (most recent call last):    File "/layers/google.python.pip/pip/lib/python3.9/site-packages/gunicorn/arbiter.py", line 609, in spawn_worker      worker.init_process()    File "/layers/google.python.pip/pip/lib/python3.9/site-packages/gunicorn/workers/gthread.py", line 95, in init_process      super().init_process()    File "/layers/google.python.pip/pip/lib/python3.9/site-packages/gunicorn/workers/base.py", line 134, in init_process      self.load_wsgi()    File "/layers/google.python.pip/pip/lib/python3.9/site-packages/gunicorn/workers/base.py", line 146, in load_wsgi      self.wsgi = self.app.wsgi()    File "/layers/google.python.pip/pip/lib/python3.9/site-packages/gunicorn/app/base.py", line 67, in wsgi      self.callable = self.load()    File "/layers/google.python.pip/pip/lib/python3.9/site-packages/gunicorn/app/wsgiapp.py", line 58, in load      return self.load_wsgiapp()    File "/layers/google.python.pip/pip/lib/python3.9/site-packages/gunicorn/app/wsgiapp.py", line 48, in load_wsgiapp      return util.import_app(self.app_uri)    File "/layers/google.python.pip/pip/lib/python3.9/site-packages/gunicorn/util.py", line 371, in import_app      mod = importlib.import_module(module)    File "/layers/google.python.runtime/python/lib/python3.9/importlib/__init__.py", line 127, in import_module      return _bootstrap._gcd_import(name[level:], package, level)    File "<frozen importlib._bootstrap>", line 1030, in _gcd_import    File "<frozen importlib._bootstrap>", line 1007, in _find_and_load    File "<frozen importlib._bootstrap>", line 984, in _find_and_load_unlocked  ModuleNotFoundError: No module named 'main'
2024-01-13 07:27:20 default[20240112t232125]  [2024-01-13 07:27:20 +0000] [20] [INFO] Worker exiting (pid: 20)
2024-01-13 07:27:20 default[20240112t232125]  [2024-01-13 07:27:20 +0000] [22] [INFO] Booting worker with pid: 22
2024-01-13 07:27:20 default[20240112t232125]  [2024-01-13 07:27:20 +0000] [23] [INFO] Booting worker with pid: 23
2024-01-13 07:27:20 default[20240112t232125]  [2024-01-13 07:27:20 +0000] [22] [ERROR] Exception in worker process
2024-01-13 07:27:20 default[20240112t232125]  Traceback (most recent call last):    File "/layers/google.python.pip/pip/lib/python3.9/site-packages/gunicorn/arbiter.py", line 609, in spawn_worker      worker.init_process()    File "/layers/google.python.pip/pip/lib/python3.9/site-packages/gunicorn/workers/gthread.py", line 95, in init_process      super().init_process()    File "/layers/google.python.pip/pip/lib/python3.9/site-packages/gunicorn/workers/base.py", line 134, in init_process      self.load_wsgi()    File "/layers/google.python.pip/pip/lib/python3.9/site-packages/gunicorn/workers/base.py", line 146, in load_wsgi      self.wsgi = self.app.wsgi()    File "/layers/google.python.pip/pip/lib/python3.9/site-packages/gunicorn/app/base.py", line 67, in wsgi      self.callable = self.load()    File "/layers/google.python.pip/pip/lib/python3.9/site-packages/gunicorn/app/wsgiapp.py", line 58, in load      return self.load_wsgiapp()    File "/layers/google.python.pip/pip/lib/python3.9/site-packages/gunicorn/app/wsgiapp.py", line 48, in load_wsgiapp      return util.import_app(self.app_uri)    File "/layers/google.python.pip/pip/lib/python3.9/site-packages/gunicorn/util.py", line 371, in import_app      mod = importlib.import_module(module)    File "/layers/google.python.runtime/python/lib/python3.9/importlib/__init__.py", line 127, in import_module      return _bootstrap._gcd_import(name[level:], package, level)    File "<frozen importlib._bootstrap>", line 1030, in _gcd_import    File "<frozen importlib._bootstrap>", line 1007, in _find_and_load    File "<frozen importlib._bootstrap>", line 984, in _find_and_load_unlocked  ModuleNotFoundError: No module named 'main'
2024-01-13 07:27:20 default[20240112t232125]  [2024-01-13 07:27:20 +0000] [22] [INFO] Worker exiting (pid: 22)
2024-01-13 07:27:20 default[20240112t232125]  [2024-01-13 07:27:20 +0000] [11] [ERROR] Worker (pid:20) exited with code 3
2024-01-13 07:27:20 default[20240112t232125]  Exception ignored in: <function _releaseLock at 0x3e185d588160>
2024-01-13 07:27:20 default[20240112t232125]  Traceback (most recent call last):    File "/layers/google.python.runtime/python/lib/python3.9/logging/__init__.py", line 232, in _releaseLock  [2024-01-13 07:27:20 +0000] [23] [ERROR] Exception in worker process
2024-01-13 07:27:20 default[20240112t232125]  Traceback (most recent call last):    File "/layers/google.python.pip/pip/lib/python3.9/site-packages/gunicorn/arbiter.py", line 609, in spawn_worker      worker.init_process()    File "/layers/google.python.pip/pip/lib/python3.9/site-packages/gunicorn/workers/gthread.py", line 95, in init_process      super().init_process()    File "/layers/google.python.pip/pip/lib/python3.9/site-packages/gunicorn/workers/base.py", line 134, in init_process      self.load_wsgi()    File "/layers/google.python.pip/pip/lib/python3.9/site-packages/gunicorn/workers/base.py", line 146, in load_wsgi      self.wsgi = self.app.wsgi()    File "/layers/google.python.pip/pip/lib/python3.9/site-packages/gunicorn/app/base.py", line 67, in wsgi      self.callable = self.load()    File "/layers/google.python.pip/pip/lib/python3.9/site-packages/gunicorn/app/wsgiapp.py", line 58, in load      return self.load_wsgiapp()    File "/layers/google.python.pip/pip/lib/python3.9/site-packages/gunicorn/app/wsgiapp.py", line 48, in load_wsgiapp      return util.import_app(self.app_uri)    File "/layers/google.python.pip/pip/lib/python3.9/site-packages/gunicorn/util.py", line 371, in import_app      mod = importlib.import_module(module)    File "/layers/google.python.runtime/python/lib/python3.9/importlib/__init__.py", line 127, in import_module      return _bootstrap._gcd_import(name[level:], package, level)    File "<frozen importlib._bootstrap>", line 1030, in _gcd_import    File "<frozen importlib._bootstrap>", line 1007, in _find_and_load    File "<frozen importlib._bootstrap>", line 984, in _find_and_load_unlocked  ModuleNotFoundError: No module named 'main'
2024-01-13 07:27:20 default[20240112t232125]  [2024-01-13 07:27:20 +0000] [23] [INFO] Worker exiting (pid: 23)
2024-01-13 07:27:20 default[20240112t232125]      _lock.release()
2024-01-13 07:27:20 default[20240112t232125]    File "/layers/google.python.pip/pip/lib/python3.9/site-packages/gunicorn/arbiter.py", line 242, in handle_chld
2024-01-13 07:27:20 default[20240112t232125]      self.reap_workers()
2024-01-13 07:27:20 default[20240112t232125]    File "/layers/google.python.pip/pip/lib/python3.9/site-packages/gunicorn/arbiter.py", line 530, in reap_workers
2024-01-13 07:27:20 default[20240112t232125]  [2024-01-13 07:27:20 +0000] [24] [INFO] Booting worker with pid: 24
2024-01-13 07:27:20 default[20240112t232125]      raise HaltServer(reason, self.WORKER_BOOT_ERROR)
2024-01-13 07:27:20 default[20240112t232125]  gunicorn.errors.HaltServer: <HaltServer 'Worker failed to boot.' 3>
2024-01-13 07:27:20 default[20240112t232125]  [2024-01-13 07:27:20 +0000] [24] [ERROR] Exception in worker process
2024-01-13 07:27:20 default[20240112t232125]  Traceback (most recent call last):    File "/layers/google.python.pip/pip/lib/python3.9/site-packages/gunicorn/arbiter.py", line 609, in spawn_worker      worker.init_process()    File "/layers/google.python.pip/pip/lib/python3.9/site-packages/gunicorn/workers/gthread.py", line 95, in init_process      super().init_process()    File "/layers/google.python.pip/pip/lib/python3.9/site-packages/gunicorn/workers/base.py", line 134, in init_process      self.load_wsgi()    File "/layers/google.python.pip/pip/lib/python3.9/site-packages/gunicorn/workers/base.py", line 146, in load_wsgi      self.wsgi = self.app.wsgi()    File "/layers/google.python.pip/pip/lib/python3.9/site-packages/gunicorn/app/base.py", line 67, in wsgi      self.callable = self.load()    File "/layers/google.python.pip/pip/lib/python3.9/site-packages/gunicorn/app/wsgiapp.py", line 58, in load      return self.load_wsgiapp()    File "/layers/google.python.pip/pip/lib/python3.9/site-packages/gunicorn/app/wsgiapp.py", line 48, in load_wsgiapp      return util.import_app(self.app_uri)    File "/layers/google.python.pip/pip/lib/python3.9/site-packages/gunicorn/util.py", line 371, in import_app      mod = importlib.import_module(module)    File "/layers/google.python.runtime/python/lib/python3.9/importlib/__init__.py", line 127, in import_module      return _bootstrap._gcd_import(name[level:], package, level)    File "<frozen importlib._bootstrap>", line 1030, in _gcd_import    File "<frozen importlib._bootstrap>", line 1007, in _find_and_load    File "<frozen importlib._bootstrap>", line 984, in _find_and_load_unlocked  ModuleNotFoundError: No module named 'main'
2024-01-13 07:27:20 default[20240112t232125]  [2024-01-13 07:27:20 +0000] [24] [INFO] Worker exiting (pid: 24)
2024-01-13 07:27:20 default[20240112t232125]  [2024-01-13 07:27:20 +0000] [11] [ERROR] Worker (pid:22) exited with code 3
2024-01-13 07:27:20 default[20240112t232125]  [2024-01-13 07:27:20 +0000] [11] [ERROR] Worker (pid:23) was sent SIGTERM!
2024-01-13 07:27:20 default[20240112t232125]  [2024-01-13 07:27:20 +0000] [11] [ERROR] Worker (pid:24) was sent SIGTERM!
2024-01-13 07:27:20 default[20240112t232125]  [2024-01-13 07:27:20 +0000] [11] [ERROR] Shutting down: Master
2024-01-13 07:27:20 default[20240112t232125]  [2024-01-13 07:27:20 +0000] [11] [ERROR] Reason: Worker failed to boot.
2024-01-13 07:27:20 default[20240112t232125]  "GET /favicon.ico HTTP/1.1" 500
2024-01-13 07:30:52 default[20240112t232125]  "GET / HTTP/1.1" 502
2024-01-13 07:30:53 default[20240112t232125]  [2024-01-13 07:30:53 +0000] [11] [INFO] Starting gunicorn 21.2.0
2024-01-13 07:30:53 default[20240112t232125]  [2024-01-13 07:30:53 +0000] [11] [INFO] Listening at: http://0.0.0.0:8081 (11)
2024-01-13 07:30:53 default[20240112t232125]  [2024-01-13 07:30:53 +0000] [11] [INFO] Using worker: gthread
2024-01-13 07:30:53 default[20240112t232125]  [2024-01-13 07:30:53 +0000] [19] [INFO] Booting worker with pid: 19
2024-01-13 07:30:53 default[20240112t232125]  [2024-01-13 07:30:53 +0000] [19] [ERROR] Exception in worker process
2024-01-13 07:30:53 default[20240112t232125]  Traceback (most recent call last):    File "/layers/google.python.pip/pip/lib/python3.9/site-packages/gunicorn/arbiter.py", line 609, in spawn_worker      worker.init_process()    File "/layers/google.python.pip/pip/lib/python3.9/site-packages/gunicorn/workers/gthread.py", line 95, in init_process      super().init_process()    File "/layers/google.python.pip/pip/lib/python3.9/site-packages/gunicorn/workers/base.py", line 134, in init_process      self.load_wsgi()    File "/layers/google.python.pip/pip/lib/python3.9/site-packages/gunicorn/workers/base.py", line 146, in load_wsgi      self.wsgi = self.app.wsgi()    File "/layers/google.python.pip/pip/lib/python3.9/site-packages/gunicorn/app/base.py", line 67, in wsgi      self.callable = self.load()    File "/layers/google.python.pip/pip/lib/python3.9/site-packages/gunicorn/app/wsgiapp.py", line 58, in load      return self.load_wsgiapp()    File "/layers/google.python.pip/pip/lib/python3.9/site-packages/gunicorn/app/wsgiapp.py", line 48, in load_wsgiapp      return util.import_app(self.app_uri)    File "/layers/google.python.pip/pip/lib/python3.9/site-packages/gunicorn/util.py", line 371, in import_app      mod = importlib.import_module(module)    File "/layers/google.python.runtime/python/lib/python3.9/importlib/__init__.py", line 127, in import_module      return _bootstrap._gcd_import(name[level:], package, level)    File "<frozen importlib._bootstrap>", line 1030, in _gcd_import    File "<frozen importlib._bootstrap>", line 1007, in _find_and_load    File "<frozen importlib._bootstrap>", line 984, in _find_and_load_unlocked  ModuleNotFoundError: No module named 'main'
2024-01-13 07:30:53 default[20240112t232125]  [2024-01-13 07:30:53 +0000] [19] [INFO] Worker exiting (pid: 19)
2024-01-13 07:30:53 default[20240112t232125]  [2024-01-13 07:30:53 +0000] [22] [INFO] Booting worker with pid: 22
2024-01-13 07:30:53 default[20240112t232125]  [2024-01-13 07:30:53 +0000] [22] [ERROR] Exception in worker process
2024-01-13 07:30:53 default[20240112t232125]  Traceback (most recent call last):    File "/layers/google.python.pip/pip/lib/python3.9/site-packages/gunicorn/arbiter.py", line 609, in spawn_worker      worker.init_process()    File "/layers/google.python.pip/pip/lib/python3.9/site-packages/gunicorn/workers/gthread.py", line 95, in init_process      super().init_process()    File "/layers/google.python.pip/pip/lib/python3.9/site-packages/gunicorn/workers/base.py", line 134, in init_process      self.load_wsgi()    File "/layers/google.python.pip/pip/lib/python3.9/site-packages/gunicorn/workers/base.py", line 146, in load_wsgi      self.wsgi = self.app.wsgi()    File "/layers/google.python.pip/pip/lib/python3.9/site-packages/gunicorn/app/base.py", line 67, in wsgi      self.callable = self.load()    File "/layers/google.python.pip/pip/lib/python3.9/site-packages/gunicorn/app/wsgiapp.py", line 58, in load      return self.load_wsgiapp()    File "/layers/google.python.pip/pip/lib/python3.9/site-packages/gunicorn/app/wsgiapp.py", line 48, in load_wsgiapp      return util.import_app(self.app_uri)    File "/layers/google.python.pip/pip/lib/python3.9/site-packages/gunicorn/util.py", line 371, in import_app      mod = importlib.import_module(module)    File "/layers/google.python.runtime/python/lib/python3.9/importlib/__init__.py", line 127, in import_module      return _bootstrap._gcd_import(name[level:], package, level)    File "<frozen importlib._bootstrap>", line 1030, in _gcd_import    File "<frozen importlib._bootstrap>", line 1007, in _find_and_load    File "<frozen importlib._bootstrap>", line 984, in _find_and_load_unlocked  ModuleNotFoundError: No module named 'main'
2024-01-13 07:30:53 default[20240112t232125]  [2024-01-13 07:30:53 +0000] [22] [INFO] Worker exiting (pid: 22)
2024-01-13 07:30:53 default[20240112t232125]  [2024-01-13 07:30:53 +0000] [11] [ERROR] Worker (pid:19) exited with code 3
2024-01-13 07:30:53 default[20240112t232125]  [2024-01-13 07:30:53 +0000] [23] [INFO] Booting worker with pid: 23
2024-01-13 07:30:53 default[20240112t232125]  [2024-01-13 07:30:53 +0000] [11] [ERROR] Worker (pid:22) was sent SIGTERM!
2024-01-13 07:30:53 default[20240112t232125]  [2024-01-13 07:30:53 +0000] [23] [ERROR] Exception in worker process
2024-01-13 07:30:53 default[20240112t232125]  Traceback (most recent call last):    File "/layers/google.python.pip/pip/lib/python3.9/site-packages/gunicorn/arbiter.py", line 609, in spawn_worker      worker.init_process()    File "/layers/google.python.pip/pip/lib/python3.9/site-packages/gunicorn/workers/gthread.py", line 95, in init_process      super().init_process()    File "/layers/google.python.pip/pip/lib/python3.9/site-packages/gunicorn/workers/base.py", line 134, in init_process      self.load_wsgi()    File "/layers/google.python.pip/pip/lib/python3.9/site-packages/gunicorn/workers/base.py", line 146, in load_wsgi      self.wsgi = self.app.wsgi()    File "/layers/google.python.pip/pip/lib/python3.9/site-packages/gunicorn/app/base.py", line 67, in wsgi      self.callable = self.load()    File "/layers/google.python.pip/pip/lib/python3.9/site-packages/gunicorn/app/wsgiapp.py", line 58, in load      return self.load_wsgiapp()    File "/layers/google.python.pip/pip/lib/python3.9/site-packages/gunicorn/app/wsgiapp.py", line 48, in load_wsgiapp      return util.import_app(self.app_uri)    File "/layers/google.python.pip/pip/lib/python3.9/site-packages/gunicorn/util.py", line 371, in import_app      mod = importlib.import_module(module)    File "/layers/google.python.runtime/python/lib/python3.9/importlib/__init__.py", line 127, in import_module      return _bootstrap._gcd_import(name[level:], package, level)    File "<frozen importlib._bootstrap>", line 1030, in _gcd_import    File "<frozen importlib._bootstrap>", line 1007, in _find_and_load    File "<frozen importlib._bootstrap>", line 984, in _find_and_load_unlocked  ModuleNotFoundError: No module named 'main'
2024-01-13 07:30:53 default[20240112t232125]  [2024-01-13 07:30:53 +0000] [23] [INFO] Worker exiting (pid: 23)
2024-01-13 07:30:53 default[20240112t232125]  [2024-01-13 07:30:53 +0000] [11] [ERROR] Worker (pid:23) exited with code 3
2024-01-13 07:30:53 default[20240112t232125]  Traceback (most recent call last):    File "/layers/google.python.pip/pip/lib/python3.9/site-packages/gunicorn/arbiter.py", line 202, in run      self.manage_workers()    File "/layers/google.python.pip/pip/lib/python3.9/site-packages/gunicorn/arbiter.py", line 571, in manage_workers      self.spawn_workers()    File "/layers/google.python.pip/pip/lib/python3.9/site-packages/gunicorn/arbiter.py", line 642, in spawn_workers      self.spawn_worker()    File "/layers/google.python.pip/pip/lib/python3.9/site-packages/gunicorn/arbiter.py", line 242, in handle_chld      self.reap_workers()    File "/layers/google.python.pip/pip/lib/python3.9/site-packages/gunicorn/arbiter.py", line 530, in reap_workers      raise HaltServer(reason, self.WORKER_BOOT_ERROR)  gunicorn.errors.HaltServer: <HaltServer 'Worker failed to boot.' 3>
2024-01-13 07:30:53 default[20240112t232125]  During handling of the above exception, another exception occurred:
2024-01-13 07:30:53 default[20240112t232125]  Traceback (most recent call last):    File "/layers/google.python.pip/pip/bin/gunicorn", line 8, in <module>      sys.exit(run())    File "/layers/google.python.pip/pip/lib/python3.9/site-packages/gunicorn/app/wsgiapp.py", line 67, in run      WSGIApplication("%(prog)s [OPTIONS] [APP_MODULE]").run()    File "/layers/google.python.pip/pip/lib/python3.9/site-packages/gunicorn/app/base.py", line 236, in run      super().run()    File "/layers/google.python.pip/pip/lib/python3.9/site-packages/gunicorn/app/base.py", line 72, in run      Arbiter(self).run()    File "/layers/google.python.pip/pip/lib/python3.9/site-packages/gunicorn/arbiter.py", line 229, in run      self.halt(reason=inst.reason, exit_status=inst.exit_status)    File "/layers/google.python.pip/pip/lib/python3.9/site-packages/gunicorn/arbiter.py", line 342, in halt      self.stop()    File "/layers/google.python.pip/pip/lib/python3.9/site-packages/gunicorn/arbiter.py", line 396, in stop      time.sleep(0.1)    File "/layers/google.python.pip/pip/lib/python3.9/site-packages/gunicorn/arbiter.py", line 242, in handle_chld      self.reap_workers()    File "/layers/google.python.pip/pip/lib/python3.9/site-packages/gunicorn/arbiter.py", line 530, in reap_workers      raise HaltServer(reason, self.WORKER_BOOT_ERROR)  gunicorn.errors.HaltServer: <HaltServer 'Worker failed to boot.' 3>
2024-01-13 07:30:53 default[20240112t232125]  "GET /favicon.ico HTTP/1.1" 500
2024-01-13 07:54:42 default[20240112t235300]  [2024-01-13 07:54:42,101] ERROR in app: Exception on / [GET]
2024-01-13 07:54:42 default[20240112t235300]  Traceback (most recent call last):    File "/layers/google.python.pip/pip/lib/python3.9/site-packages/flask/app.py", line 1455, in wsgi_app      response = self.full_dispatch_request()    File "/layers/google.python.pip/pip/lib/python3.9/site-packages/flask/app.py", line 869, in full_dispatch_request      rv = self.handle_user_exception(e)    File "/layers/google.python.pip/pip/lib/python3.9/site-packages/flask/app.py", line 867, in full_dispatch_request      rv = self.dispatch_request()    File "/layers/google.python.pip/pip/lib/python3.9/site-packages/flask/app.py", line 852, in dispatch_request      return self.ensure_sync(self.view_functions[rule.endpoint])(**view_args)    File "/srv/main.py", line 18, in root      return render_template("index.html", times=dummy_times)    File "/layers/google.python.pip/pip/lib/python3.9/site-packages/flask/templating.py", line 151, in render_template      template = app.jinja_env.get_or_select_template(template_name_or_list)    File "/layers/google.python.pip/pip/lib/python3.9/site-packages/jinja2/environment.py", line 1081, in get_or_select_template      return self.get_template(template_name_or_list, parent, globals)    File "/layers/google.python.pip/pip/lib/python3.9/site-packages/jinja2/environment.py", line 1010, in get_template      return self._load_template(name, globals)    File "/layers/google.python.pip/pip/lib/python3.9/site-packages/jinja2/environment.py", line 969, in _load_template      template = self.loader.load(self, name, self.make_globals(globals))    File "/layers/google.python.pip/pip/lib/python3.9/site-packages/jinja2/loaders.py", line 125, in load      source, filename, uptodate = self.get_source(environment, name)    File "/layers/google.python.pip/pip/lib/python3.9/site-packages/flask/templating.py", line 65, in get_source      return self._get_source_fast(environment, template)    File "/layers/google.python.pip/pip/lib/python3.9/site-packages/flask/templating.py", line 99, in _get_source_fast      raise TemplateNotFound(template)  jinja2.exceptions.TemplateNotFound: index.html
2024-01-13 07:54:42 default[20240112t235300]  "GET /favicon.ico HTTP/1.1" 404
2024-01-13 07:54:46 default[20240112t235300]  [2024-01-13 07:54:46,098] ERROR in app: Exception on / [GET]
